<?xml version="1.0" encoding="utf-8"?>
<!-- =================================================================================== -->
<!--   Copyright 2019 ANYbotics, https://www.anybotics.com                               -->
<!-- =================================================================================== -->
<!-- This file contains the description of the ANYmal B robot. -->
<robot name="anymal"
    xmlns:xacro="http://www.ros.org/wiki/xacro"> 
 
    <!-- Material for the visual primitives -->  
    <material name="anymal_material">    
        <color rgba="0.7 0.7 0.7 1.0"/>  
    </material>  
    <!-- Base link -->  
    <link name="base">    
        <visual>      
            <origin rpy="0 0 0" xyz="0 0 0"/>      
            <geometry>        
                <mesh filename="package://anymal_b_simple_description/meshes/anymal_base.dae" scale="0.001 0.001     0.001"/>      
            </geometry>      
            <material name="anymal_material"/>    
        </visual>    
        <collision>      
            <!-- Main Body -->      
            <origin rpy="0 0 0" xyz="0 0 0.08"/>      
            <geometry>        
                <box size="0.531 0.27 0.24"/>      
            </geometry>    
        </collision>    
        <collision>      
            <!-- HAA actuators -->      
            <origin rpy="0 1.57079632679 0" xyz="0.227 0.116 0"/>      
            <geometry>        
                <cylinder length="0.1" radius="0.05"/>      
            </geometry>    
        </collision>    
        <collision>      
            <origin rpy="0 1.57079632679 0" xyz="0.227 -0.116 0"/>      
            <geometry>        
                <cylinder length="0.1" radius="0.05"/>      
            </geometry>    
        </collision>    
        <collision>      
            <origin rpy="0 1.57079632679 0" xyz="-0.227 0.116 0"/>      
            <geometry>        
                <cylinder length="0.1" radius="0.05"/>      
            </geometry>    
        </collision>    
        <collision>      
            <origin rpy="0 1.57079632679 0" xyz="-0.227 -0.116 0"/>      
            <geometry>        
                <cylinder length="0.1" radius="0.05"/>      
            </geometry>    
        </collision>    
        <collision>      
            <!-- Belly plate front bump -->      
            <origin rpy="0 0 0" xyz="0.2155 0.0 -0.09"/>      
            <geometry>        
                <box size="0.1 0.1 0.07"/>      
            </geometry>    
        </collision>    
        <collision>      
            <!-- Belly plate hind bump-->      
            <origin rpy="0 0 0" xyz="-0.2155 0.0 -0.09"/>      
            <geometry>        
                <box size="0.1 0.1 0.07"/>      
            </geometry>    
        </collision>    
        <collision>      
            <!-- Belly plate middle bump-->      
            <origin rpy="0 0 0" xyz="0 0 -0.09"/>      
            <geometry>        
                <box size="0.531 0.02 0.07"/>      
            </geometry>    
        </collision> 

 <!-- Kinect  
        <collision>      
            <origin rpy="0 0 0" xyz="0 0 1.0"/>      
            <geometry>        
                <box size="0.531 0.02 0.07"/>      
            </geometry>    
        </collision>  --> 
    </link>  



    <!-- Fixed joint to add dummy inertia link -->  
    <joint name="base_to_base_inertia" type="fixed">    
        <parent link="base"/>    
        <child link="base_inertia"/>    
        <origin rpy="0 0 0" xyz="0 0 0"/>  
    </joint>  
    <!-- Dummy inertia link, because KDL cannot have inertia on the base link -->  
    <link name="base_inertia">    
        <inertial>      
            <origin rpy="0 0 0" xyz="-0.001960558279 -0.001413217745 0.050207125344"/>      
            <mass value="16.793507758"/>      
            <inertia ixx="0.217391101503" ixy="-0.00132873239126" ixz="-0.00228200226173" iyy="0.639432546734" iyz="-0.00138078263145" izz="0.62414077654"/>    
        </inertial>  
    </link>

    <!-- IMU on base_inertia link -->
    <gazebo reference="base_inertia">
        <gravity>true</gravity>
        <sensor name="imu_sensor" type="imu">
          <always_on>true</always_on>
          <update_rate>50</update_rate>
          <visualize>true</visualize>
          <topic>__default_topic__</topic>
          <plugin filename="libgazebo_ros_imu_sensor.so" name="imu_plugin">
            <topicName>anymal/imu/data</topicName>
            <bodyName>base</bodyName>
            <updateRateHZ>50.0</updateRateHZ>
            <gaussianNoise>0</gaussianNoise>
            <xyzOffset>0 0 0</xyzOffset>
            <rpyOffset>0 0 0</rpyOffset>
            <!--<frameName>base</frameName>-->
            <frameName>base_inertia</frameName>
            <initialOrientationAsReference>false</initialOrientationAsReference>
          </plugin>
          <pose>0 0 0 0 0 0</pose>
        </sensor>
    </gazebo>

    <link name="LF_HIP">    
        <visual>      
            <origin rpy="0 0 0.0" xyz="0 0 0"/>      
            <geometry>        
                <mesh filename="package://anymal_b_simple_description/meshes/anymal_hip_l.dae" scale="0.001 0.001     0.001"/>      
            </geometry>      
            <material name="anymal_material"/>    
        </visual>    
        <collision>      
            <!-- Protector -->      
            <origin rpy="1.57079632679 0 0" xyz="0.0635 -0.009 0.0"/>      
            <geometry>        
                <cylinder length="0.1" radius="0.08"/>      
            </geometry>    
        </collision>    
        <collision>      
            <!-- Heatfins -->      
            <origin rpy="1.57079632679 0 0" xyz="0.0635 -0.074 0.0"/>      
            <geometry>        
                <cylinder length="0.03" radius="0.045"/>      
            </geometry>    
        </collision>    
        <inertial>      
            <origin rpy="0 0 0" xyz="0.064516258147 -0.003787101702 -0.000152184388"/>      
            <mass value="1.42462064"/>      
            <inertia ixx="0.00243023349564" ixy="-1.53023971e-05" ixz="-2.1819095354e-05" iyy="0.00230257239103" iyz="2.6473021273e-05" izz="0.0019806759227"/>    
        </inertial>  
    </link>  
    <!-- Hip joint -->  
    <joint name="LF_HAA" type="revolute">    
        <parent link="base"/>    
        <child link="LF_HIP"/>    
        <origin xyz="0.277 0.116 0.0"/>    
        <axis xyz="1 0 0"/>    
        <limit command_effort="40" current="10" effort="80" gear_velocity="10" lower="-9.42" upper="9.42" velocity="15"/>    
        <dynamics damping="0.0" friction="0.0"/>  
    </joint>  
    <link name="LF_THIGH">    
        <visual>      
            <origin rpy="0 0 0.0" xyz="0 0 0"/>      
            <geometry>        
                <mesh filename="package://anymal_b_simple_description/meshes/anymal_thigh_l.dae" scale="0.001 0.001     0.001"/>      
            </geometry>      
            <material name="anymal_material"/>    
        </visual>    
        <collision>      
            <!-- thigh with heat fins -->      
            <origin rpy="0.145 0 0" xyz="0 0.035 -0.125"/>      
            <geometry>        
                <box size="0.08 0.04 0.25"/>      
            </geometry>    
        </collision>    
        <collision>      
            <!-- KFE actuator -->      
            <origin rpy="1.57079632679 0 0" xyz="0.0 0.069 -0.25"/>      
            <geometry>        
                <cylinder length="0.12" radius="0.06"/>      
            </geometry>    
        </collision>    
        <collision>      
            <!-- upper protector -->      
            <origin rpy="1.71579632679 0 0" xyz="0 -0.005 0"/>      
            <geometry>        
                <cylinder length="0.12" radius="0.066"/>      
            </geometry>    
        </collision>    
        <inertial>      
            <origin rpy="0 0 0" xyz="-0.003897968082 0.054226618537 -0.214583373795"/>      
            <mass value="1.634976467"/>      
            <inertia ixx="0.0120367944369" ixy="6.762065206e-05" ixz="0.000287806340448" iyy="0.0120643637939" iyz="-0.00140610131218" izz="0.00249422574881"/>    
        </inertial>  
    </link>  
    <!-- Thigh joint -->  
    <joint name="LF_HFE" type="revolute">    
        <parent link="LF_HIP"/>    
        <child link="LF_THIGH"/>    
        <origin xyz="0.0635                    0.041                    0.0"/>    
        <axis xyz="0 1 0"/>    
        <limit command_effort="40" current="10" effort="80" gear_velocity="10" lower="-9.42" upper="9.42" velocity="15.0"/>    
        <dynamics damping="0.0" friction="0.0"/>  
    </joint>  
    <link name="LF_SHANK">    
        <visual>      
            <origin rpy="0 0 0.0" xyz="0 0 0"/>      
            <geometry>        
                <mesh filename="package://anymal_b_simple_description/meshes/anymal_shank_l.dae" scale="0.001 0.001     0.001"/>      
            </geometry>      
            <material name="anymal_material"/>    
        </visual>    
        <collision>      
            <origin rpy="0 1.57079632679 0" xyz="0.065 -0.015 0.01"/>      
            <geometry>        
                <box size="0.08 0.07 0.13"/>      
            </geometry>    
        </collision>    
        <inertial>      
            <origin rpy="0 0 0" xyz="0.030816858139 -0.004617229294 0.000893125713"/>      
            <mass value="0.207204302"/>      
            <inertia ixx="0.0002104880248" ixy="-5.6750980345e-05" ixz="1.0127699391e-05" iyy="0.000676270210023" iyz="-8.22869024e-07" izz="0.000545032674924"/>    
        </inertial>  
    </link>  
    <!-- Shank joint -->  
    <joint name="LF_KFE" type="revolute">    
        <parent link="LF_THIGH"/>    
        <child link="LF_SHANK"/>    
        <origin xyz="0.0 0.109 -0.25"/>    
        <axis xyz="0 1 0"/>    
        <limit command_effort="40" current="10" effort="80" gear_velocity="10" lower="-9.42" upper="9.42" velocity="15.0"/>    
        <dynamics damping="0.0" friction="0.0"/>  
    </joint>  
    <!-- Shank to Adapter joint -->  
    <joint name="LF_SHANK_TO_ADAPTER" type="fixed">    
        <parent link="LF_SHANK"/>    
        <child link="LF_ADAPTER"/>    
        <origin rpy="0.0 0.0 0.0" xyz="0.1 -0.02 0.0"/>  
    </joint>  
    <!-- Adapter link -->  
    <link name="LF_ADAPTER">    
        <visual>      
            <origin rpy="0 0 0.0" xyz="0 0 0.032"/>      
            <geometry>        
                <mesh filename="package://anymal_b_simple_description/meshes/anymal_foot.dae" scale="0.001 0.001     0.001"/>      
            </geometry>      
            <material name="anymal_material"/>    
        </visual>    
        <collision>      
            <origin rpy="0 0 0" xyz="0 0 -0.160625"/>      
            <geometry>        
                <cylinder length="0.32125" radius="0.015"/>      
            </geometry>      
            <material name="anymal_material"/>    
        </collision>    
        <inertial>      
            <origin rpy="0 0 0" xyz="-8.66e-10 -1.472e-09 -0.244345749188"/>      
            <mass value="0.140170767"/>      
            <inertia ixx="0.00159938741862" ixy="-9.32e-13" ixz="1.039e-11" iyy="0.00159938741932" iyz="1.7563e-11" izz="5.4423177329e-05"/>    
        </inertial>  
    </link>  
    <!-- Adapter to Foot joint -->  
    <joint name="LF_ADAPTER_TO_FOOT" type="fixed">    
        <parent link="LF_ADAPTER"/>    
        <child link="LF_FOOT"/>    
        <origin rpy="0.0 0.0 0.0" xyz="0.0 0.0 -0.32125"/>  
    </joint>  
    <!-- Foot link -->  
    <link name="LF_FOOT">
 	<inertial >
            <origin xyz="0 0 0.02325" rpy="0 0 0"/>
            <mass value="0.140170767" />
            <inertia ixx="1.28e-06" ixy="0.0" ixz="0.0" iyy="1.28e-06" iyz="0.0" izz="1.28e-06"/>
        </inertial>    
        <collision name="LF_FOOT_collision">      
            <origin xyz="0 0 0.02325" rpy="0 0 0"/>      
            <geometry>        
                <sphere radius="0.031"/>      
            </geometry>    
        </collision>  
	<visual>
            <origin rpy="0.0 0 0" xyz="0 0 0"/>
            <geometry>
                <sphere radius="0.031"/>
            </geometry>
        </visual>
    </link>  
    <!-- Gazebo customization -->  
    <gazebo reference="LF_FOOT">
	<sensor name="LF_FOOT_CONTACTSENSOR" type="contact">
	    <always_on>true</always_on>
	    <updateRate>30</updateRate>
	    <contact>
		<collision>LF_FOOT_collision_collision_1</collision>
	    </contact>
	    <plugin name="bumper0_plugin" filename="libgazebo_ros_bumper.so">
		<bumperTopicName>lf_foot_contactsensor_state</bumperTopicName>
		<frameName>lf_foot_contactsesnor_link</frameName>
	    </plugin>
	</sensor>    
        <material>Gazebo/Blue</material>
        <kp>400.0</kp>
        <kd>10.0</kd>    
<!--        <mu1>1000000.0</mu1>
        <mu2>1000000.0</mu2>-->
        <mu1>0.8</mu1>
        <mu2>0.8</mu2>
    </gazebo>  
    <link name="RF_HIP">    
        <visual>      
            <origin rpy="0 0 0.0" xyz="0 0 0"/>      
            <geometry>        
                <mesh filename="package://anymal_b_simple_description/meshes/anymal_hip_r.dae" scale="0.001 0.001     0.001"/>      
            </geometry>      
            <material name="anymal_material"/>    
        </visual>    
        <collision>      
            <!-- Protector -->      
            <origin rpy="1.57079632679 0 0" xyz="0.0635 0.009 0.0"/>      
            <geometry>        
                <cylinder length="0.1" radius="0.08"/>      
            </geometry>    
        </collision>    
        <collision>      
            <!-- Heatfins -->      
            <origin rpy="1.57079632679 0 0" xyz="0.0635 0.074 0.0"/>      
            <geometry>        
                <cylinder length="0.03" radius="0.045"/>      
            </geometry>    
        </collision>    
        <inertial>      
            <origin rpy="0 0 0" xyz="0.064516258147 0.003787101702 -0.000152184388"/>      
            <mass value="1.42462064"/>      
            <inertia ixx="0.00243023349564" ixy="1.53023971e-05" ixz="-2.1819095354e-05" iyy="0.00230257239103" iyz="-2.6473021273e-05" izz="0.0019806759227"/>    
        </inertial>  
    </link>  
    <!-- Hip joint -->  
    <joint name="RF_HAA" type="revolute">    
        <parent link="base"/>    
        <child link="RF_HIP"/>    
        <origin xyz="0.277 -0.116 0.0"/>    
        <axis xyz="1 0 0"/>    
        <limit command_effort="40" current="10" effort="80" gear_velocity="10" lower="-9.42" upper="9.42" velocity="15"/>    
        <dynamics damping="0.0" friction="0.0"/>  
    </joint>  
    <link name="RF_THIGH">    
        <visual>      
            <origin rpy="0 0 0.0" xyz="0 0 0"/>      
            <geometry>        
                <mesh filename="package://anymal_b_simple_description/meshes/anymal_thigh_r.dae" scale="0.001 0.001     0.001"/>      
            </geometry>      
            <material name="anymal_material"/>    
        </visual>    
        <collision>      
            <!-- thigh with heat fins -->      
            <origin rpy="-0.145 0 0" xyz="0 -0.035 -0.125"/>      
            <geometry>        
                <box size="0.08 0.04 0.25"/>      
            </geometry>    
        </collision>    
        <collision>      
            <!-- KFE actuator -->      
            <origin rpy="1.57079632679 0 0" xyz="0.0 -0.069 -0.25"/>      
            <geometry>        
                <cylinder length="0.12" radius="0.06"/>      
            </geometry>    
        </collision>    
        <collision>      
            <!-- upper protector -->      
            <origin rpy="-1.71579632679 0 0" xyz="0 0.005 0"/>      
            <geometry>        
                <cylinder length="0.12" radius="0.066"/>      
            </geometry>    
        </collision>    
        <inertial>      
            <origin rpy="0 0 0" xyz="-0.003897968082 -0.054226618537 -0.214583373795"/>      
            <mass value="1.634976467"/>      
            <inertia ixx="0.0120367944369" ixy="-6.762065206e-05" ixz="0.000287806340448" iyy="0.0120643637939" iyz="0.00140610131218" izz="0.00249422574881"/>    
        </inertial>  
    </link>  
    <!-- Thigh joint -->  
    <joint name="RF_HFE" type="revolute">    
        <parent link="RF_HIP"/>    
        <child link="RF_THIGH"/>    
        <origin xyz="0.0635                    -0.041                    0.0"/>    
        <axis xyz="0 1 0"/>    
        <limit command_effort="40" current="10" effort="80" gear_velocity="10" lower="-9.42" upper="9.42" velocity="15.0"/>    
        <dynamics damping="0.0" friction="0.0"/>  
    </joint>  
    <link name="RF_SHANK">    
        <visual>      
            <origin rpy="0 0 0.0" xyz="0 0 0"/>      
            <geometry>        
                <mesh filename="package://anymal_b_simple_description/meshes/anymal_shank_r.dae" scale="0.001 0.001     0.001"/>      
            </geometry>      
            <material name="anymal_material"/>    
        </visual>    
        <collision>      
            <origin rpy="0 1.57079632679 0" xyz="0.065 0.015 0.01"/>      
            <geometry>        
                <box size="0.08 0.07 0.13"/>      
            </geometry>    
        </collision>    
        <inertial>      
            <origin rpy="0 0 0" xyz="0.030816858139 0.004617229294 0.000893125713"/>      
            <mass value="0.207204302"/>      
            <inertia ixx="0.0002104880248" ixy="5.6750980345e-05" ixz="1.0127699391e-05" iyy="0.000676270210023" iyz="8.22869024e-07" izz="0.000545032674924"/>    
        </inertial>  
    </link>  
    <!-- Shank joint -->  
    <joint name="RF_KFE" type="revolute">    
        <parent link="RF_THIGH"/>    
        <child link="RF_SHANK"/>    
        <origin xyz="0.0 -0.109 -0.25"/>    
        <axis xyz="0 1 0"/>    
        <limit command_effort="40" current="10" effort="80" gear_velocity="10" lower="-9.42" upper="9.42" velocity="15.0"/>    
        <dynamics damping="0.0" friction="0.0"/>  
    </joint>  
    <!-- Shank to Adapter joint -->  
    <joint name="RF_SHANK_TO_ADAPTER" type="fixed">    
        <parent link="RF_SHANK"/>    
        <child link="RF_ADAPTER"/>    
        <origin rpy="-0.0 0.0 -0.0" xyz="0.1 0.02 0.0"/>  
    </joint>  
    <!-- Adapter link -->  
    <link name="RF_ADAPTER">    
        <visual>      
            <origin rpy="0 0 0.0" xyz="0 0 0.032"/>      
            <geometry>        
                <mesh filename="package://anymal_b_simple_description/meshes/anymal_foot.dae" scale="0.001 0.001     0.001"/>      
            </geometry>      
            <material name="anymal_material"/>    
        </visual>    
        <collision>      
            <origin rpy="0 0 0" xyz="0 0 -0.160625"/>      
            <geometry>        
                <cylinder length="0.32125" radius="0.015"/>      
            </geometry>      
            <material name="anymal_material"/>    
        </collision>    
        <inertial>      
            <origin rpy="0 0 0" xyz="-8.66e-10 -1.472e-09 -0.244345749188"/>      
            <mass value="0.140170767"/>      
            <inertia ixx="0.00159938741862" ixy="-9.32e-13" ixz="1.039e-11" iyy="0.00159938741932" iyz="1.7563e-11" izz="5.4423177329e-05"/>    
        </inertial>  
    </link>  
    <!-- Adapter to Foot joint -->  
    <joint name="RF_ADAPTER_TO_FOOT" type="fixed">    
        <parent link="RF_ADAPTER"/>    
        <child link="RF_FOOT"/>    
        <origin rpy="-0.0 0.0 -0.0" xyz="0.0 -0.0 -0.32125"/>  
    </joint>  
    <!-- Foot link -->  
    <link name="RF_FOOT">    
 	<inertial >
            <origin xyz="0 0 0.02325" rpy="0 0 0"/>
            <mass value="0.140170767" />
            <inertia ixx="1.28e-06" ixy="0.0" ixz="0.0" iyy="1.28e-06" iyz="0.0" izz="1.28e-06"/>
        </inertial>    
        <collision name="RF_FOOT_collision">      
            <origin xyz="0 0 0.02325" rpy="0 0 0"/>      
            <geometry>        
                <sphere radius="0.031"/>      
            </geometry>    
        </collision>  
	<visual>
            <origin rpy="0.0 0 0" xyz="0 0 0"/>
            <geometry>               
                <sphere radius="0.031"/>
            </geometry>
        </visual>
    </link>  

    <!-- Gazebo customization -->  
    <gazebo reference="RF_FOOT">  
	<sensor name="RF_FOOT_CONTACTSENSOR" type="contact">
	    <alwaysOn>true</alwaysOn>
	    <updateRate>30</updateRate>
	    <contact>
		<collision>RF_FOOT_collision_collision_1</collision>
	    </contact>
	    <plugin name="bumper0_plugin" filename="libgazebo_ros_bumper.so">
		<bumperTopicName>rf_foot_contactsensor_state</bumperTopicName>
		<frameName>rf_foot_contactsesnor_link</frameName>
	    </plugin>
	</sensor>  
        <kp>400.0</kp>
        <kd>10.0</kd>    
<!--        <mu1>1000000.0</mu1>
        <mu2>1000000.0</mu2>-->
        <mu1>0.8</mu1>
        <mu2>0.8</mu2>
    </gazebo>  

    <link name="LH_HIP">    
        <visual>      
            <origin rpy="0 0 -3.14159265359" xyz="0 0 0"/>      
            <geometry>        
                <mesh filename="package://anymal_b_simple_description/meshes/anymal_hip_r.dae" scale="0.001 0.001     0.001"/>      
            </geometry>      
            <material name="anymal_material"/>    
        </visual>    
        <collision>      
            <!-- Protector -->      
            <origin rpy="-1.57079632679 0 0" xyz="-0.0635 -0.009 0.0"/>      
            <geometry>        
                <cylinder length="0.1" radius="0.08"/>      
            </geometry>    
        </collision>    
        <collision>      
            <!-- Heatfins -->      
            <origin rpy="-1.57079632679 0 0" xyz="-0.0635 -0.074 0.0"/>      
            <geometry>        
                <cylinder length="0.03" radius="0.045"/>      
            </geometry>    
        </collision>    
        <inertial>      
            <origin rpy="0 0 0" xyz="-0.064516258147 -0.003787101702 -0.000152184388"/>      
            <mass value="1.42462064"/>      
            <inertia ixx="0.00243023349564" ixy="1.53023971e-05" ixz="2.1819095354e-05" iyy="0.00230257239103" iyz="2.6473021273e-05" izz="0.0019806759227"/>    
        </inertial>  
    </link>  
    <!-- Hip joint -->  
    <joint name="LH_HAA" type="revolute">    
        <parent link="base"/>    
        <child link="LH_HIP"/>    
        <origin xyz="-0.277 0.116 0.0"/>    
        <axis xyz="1 0 0"/>    
        <limit command_effort="40" current="10" effort="80" gear_velocity="10" lower="-9.42" upper="9.42" velocity="15"/>    
        <dynamics damping="0.0" friction="0.0"/>  
    </joint>  
    <link name="LH_THIGH">    
        <visual>      
            <origin rpy="0 0 -3.14159265359" xyz="0 0 0"/>      
            <geometry>        
                <mesh filename="package://anymal_b_simple_description/meshes/anymal_thigh_r.dae" scale="0.001 0.001     0.001"/>      
            </geometry>      
            <material name="anymal_material"/>    
        </visual>    
        <collision>      
            <!-- thigh with heat fins -->      
            <origin rpy="0.145 0 0" xyz="0 0.035 -0.125"/>      
            <geometry>        
                <box size="0.08 0.04 0.25"/>      
            </geometry>    
        </collision>    
        <collision>      
            <!-- KFE actuator -->      
            <origin rpy="1.57079632679 0 0" xyz="0.0 0.069 -0.25"/>      
            <geometry>        
                <cylinder length="0.12" radius="0.06"/>      
            </geometry>    
        </collision>    
        <collision>      
            <!-- upper protector -->      
            <origin rpy="1.71579632679 0 0" xyz="0 -0.005 0"/>      
            <geometry>        
                <cylinder length="0.12" radius="0.066"/>      
            </geometry>    
        </collision>    
        <inertial>      
            <origin rpy="0 0 0" xyz="0.003897968082 0.054226618537 -0.214583373795"/>      
            <mass value="1.634976467"/>      
            <inertia ixx="0.0120367944369" ixy="-6.762065206e-05" ixz="-0.000287806340448" iyy="0.0120643637939" iyz="-0.00140610131218" izz="0.00249422574881"/>    
        </inertial>  
    </link>  
    <!-- Thigh joint -->  
    <joint name="LH_HFE" type="revolute">    
        <parent link="LH_HIP"/>    
        <child link="LH_THIGH"/>    
        <origin xyz="-0.0635                    0.041                    0.0"/>    
        <axis xyz="0 1 0"/>    
        <limit command_effort="40" current="10" effort="80" gear_velocity="10" lower="-9.42" upper="9.42" velocity="15.0"/>    
        <dynamics damping="0.0" friction="0.0"/>  
    </joint>  
    <link name="LH_SHANK">    
        <visual>      
            <origin rpy="0 0 -3.14159265359" xyz="0 0 0"/>      
            <geometry>        
                <mesh filename="package://anymal_b_simple_description/meshes/anymal_shank_r.dae" scale="0.001 0.001     0.001"/>      
            </geometry>      
            <material name="anymal_material"/>    
        </visual>    
        <collision>      
            <origin rpy="0 1.57079632679 0" xyz="-0.065 -0.015 0.01"/>      
            <geometry>        
                <box size="0.08 0.07 0.13"/>      
            </geometry>    
        </collision>    
        <inertial>      
            <origin rpy="0 0 0" xyz="-0.030816858139 -0.004617229294 0.000893125713"/>      
            <mass value="0.207204302"/>      
            <inertia ixx="0.0002104880248" ixy="5.6750980345e-05" ixz="-1.0127699391e-05" iyy="0.000676270210023" iyz="-8.22869024e-07" izz="0.000545032674924"/>    
        </inertial>  
    </link>  
    <!-- Shank joint -->  
    <joint name="LH_KFE" type="revolute">    
        <parent link="LH_THIGH"/>    
        <child link="LH_SHANK"/>    
        <origin xyz="-0.0 0.109 -0.25"/>    
        <axis xyz="0 1 0"/>    
        <limit command_effort="40" current="10" effort="80" gear_velocity="10" lower="-9.42" upper="9.42" velocity="15.0"/>    
        <dynamics damping="0.0" friction="0.0"/>  
    </joint>  
    <!-- Shank to Adapter joint -->  
    <joint name="LH_SHANK_TO_ADAPTER" type="fixed">    
        <parent link="LH_SHANK"/>    
        <child link="LH_ADAPTER"/>    
        <origin rpy="0.0 -0.0 -0.0" xyz="-0.1 -0.02 0.0"/>  
    </joint>  
    <!-- Adapter link -->  
    <link name="LH_ADAPTER">    
        <visual>      
            <origin rpy="0 0 -3.14159265359" xyz="0 0 0.032"/>      
            <geometry>        
                <mesh filename="package://anymal_b_simple_description/meshes/anymal_foot.dae" scale="0.001 0.001     0.001"/>      
            </geometry>      
            <material name="anymal_material"/>    
        </visual>    
        <collision>      
            <origin rpy="0 0 0" xyz="0 0 -0.160625"/>      
            <geometry>        
                <cylinder length="0.32125" radius="0.015"/>      
            </geometry>      
            <material name="anymal_material"/>    
        </collision>    
        <inertial>      
            <origin rpy="0 0 0" xyz="-8.66e-10 -1.472e-09 -0.244345749188"/>      
            <mass value="0.140170767"/>      
            <inertia ixx="0.00159938741862" ixy="-9.32e-13" ixz="1.039e-11" iyy="0.00159938741932" iyz="1.7563e-11" izz="5.4423177329e-05"/>    
        </inertial>  
    </link>  
    <!-- Adapter to Foot joint -->  
    <joint name="LH_ADAPTER_TO_FOOT" type="fixed">    
        <parent link="LH_ADAPTER"/>    
        <child link="LH_FOOT"/>    
        <origin rpy="0.0 -0.0 -0.0" xyz="-0.0 0.0 -0.32125"/>  
    </joint>  
    <!-- Foot link -->  
    <link name="LH_FOOT">    
 	<inertial >
            <origin xyz="0 0 0.02325" rpy="0 0 0"/>
            <mass value="0.140170767" />
            <inertia ixx="1.28e-06" ixy="0.0" ixz="0.0" iyy="1.28e-06" iyz="0.0" izz="1.28e-06"/>
        </inertial>    
        <collision name="LH_FOOT_collision">      
            <origin xyz="0 0 0.02325" rpy="0 0 0"/>      
            <geometry>        
                <sphere radius="0.031"/>      
            </geometry>    
        </collision>  
	<visual>
            <origin rpy="0.0 0 0" xyz="0 0 0"/>
            <geometry>
                <sphere radius="0.031"/>
            </geometry>
        </visual>
    </link>  
    <!-- Gazebo customization -->  
    <gazebo reference="LH_FOOT">
	<sensor name="LH_FOOT_CONTACTSENSOR" type="contact">
	    <alwaysOn>true</alwaysOn>
	    <updateRate>30</updateRate>
	    <contact>
		<collision>LH_FOOT_collision_collision_1</collision>
	    </contact>
	    <plugin name="bumper0_plugin" filename="libgazebo_ros_bumper.so">
		<bumperTopicName>lh_foot_contactsensor_state</bumperTopicName>
		<frameName>lh_foot_contactsesnor_link</frameName>
	    </plugin>
	</sensor>    
        <kp>400.0</kp>
        <kd>10.0</kd>    
<!--        <mu1>1000000.0</mu1>
        <mu2>1000000.0</mu2>-->
        <mu1>0.8</mu1>
        <mu2>0.8</mu2>
    </gazebo>  
    <link name="RH_HIP">    
        <visual>      
            <origin rpy="0 0 -3.14159265359" xyz="0 0 0"/>      
            <geometry>        
                <mesh filename="package://anymal_b_simple_description/meshes/anymal_hip_l.dae" scale="0.001 0.001     0.001"/>      
            </geometry>      
            <material name="anymal_material"/>    
        </visual>    
        <collision>      
            <!-- Protector -->      
            <origin rpy="-1.57079632679 0 0" xyz="-0.0635 0.009 0.0"/>      
            <geometry>        
                <cylinder length="0.1" radius="0.08"/>      
            </geometry>    
        </collision>    
        <collision>      
            <!-- Heatfins -->      
            <origin rpy="-1.57079632679 0 0" xyz="-0.0635 0.074 0.0"/>      
            <geometry>        
                <cylinder length="0.03" radius="0.045"/>      
            </geometry>    
        </collision>    
        <inertial>      
            <origin rpy="0 0 0" xyz="-0.064516258147 0.003787101702 -0.000152184388"/>      
            <mass value="1.42462064"/>      
            <inertia ixx="0.00243023349564" ixy="-1.53023971e-05" ixz="2.1819095354e-05" iyy="0.00230257239103" iyz="-2.6473021273e-05" izz="0.0019806759227"/>    
        </inertial>  
    </link>  
    <!-- Hip joint -->  
    <joint name="RH_HAA" type="revolute">    
        <parent link="base"/>    
        <child link="RH_HIP"/>    
        <origin xyz="-0.277 -0.116 0.0"/>    
        <axis xyz="1 0 0"/>    
        <limit command_effort="40" current="10" effort="80" gear_velocity="10" lower="-9.42" upper="9.42" velocity="15"/>    
        <dynamics damping="0.0" friction="0.0"/>  
    </joint>  
    <link name="RH_THIGH">    
        <visual>      
            <origin rpy="0 0 -3.14159265359" xyz="0 0 0"/>      
            <geometry>        
                <mesh filename="package://anymal_b_simple_description/meshes/anymal_thigh_l.dae" scale="0.001 0.001     0.001"/>      
            </geometry>      
            <material name="anymal_material"/>    
        </visual>    
        <collision>      
            <!-- thigh with heat fins -->      
            <origin rpy="-0.145 0 0" xyz="0 -0.035 -0.125"/>      
            <geometry>        
                <box size="0.08 0.04 0.25"/>      
            </geometry>    
        </collision>    
        <collision>      
            <!-- KFE actuator -->      
            <origin rpy="1.57079632679 0 0" xyz="0.0 -0.069 -0.25"/>      
            <geometry>        
                <cylinder length="0.12" radius="0.06"/>      
            </geometry>    
        </collision>    
        <collision>      
            <!-- upper protector -->      
            <origin rpy="-1.71579632679 0 0" xyz="0 0.005 0"/>      
            <geometry>        
                <cylinder length="0.12" radius="0.066"/>      
            </geometry>    
        </collision>    
        <inertial>      
            <origin rpy="0 0 0" xyz="0.003897968082 -0.054226618537 -0.214583373795"/>      
            <mass value="1.634976467"/>      
            <inertia ixx="0.0120367944369" ixy="6.762065206e-05" ixz="-0.000287806340448" iyy="0.0120643637939" iyz="0.00140610131218" izz="0.00249422574881"/>    
        </inertial>  
    </link>  
    <!-- Thigh joint -->  
    <joint name="RH_HFE" type="revolute">    
        <parent link="RH_HIP"/>    
        <child link="RH_THIGH"/>    
        <origin xyz="-0.0635                    -0.041                    0.0"/>    
        <axis xyz="0 1 0"/>    
        <limit command_effort="40" current="10" effort="80" gear_velocity="10" lower="-9.42" upper="9.42" velocity="15.0"/>    
        <dynamics damping="0.0" friction="0.0"/>  
    </joint>  
    <link name="RH_SHANK">    
        <visual>      
            <origin rpy="0 0 -3.14159265359" xyz="0 0 0"/>      
            <geometry>        
                <mesh filename="package://anymal_b_simple_description/meshes/anymal_shank_l.dae" scale="0.001 0.001     0.001"/>      
            </geometry>      
            <material name="anymal_material"/>    
        </visual>    
        <collision>      
            <origin rpy="0 1.57079632679 0" xyz="-0.065 0.015 0.01"/>      
            <geometry>        
                <box size="0.08 0.07 0.13"/>      
            </geometry>    
        </collision>    
        <inertial>      
            <origin rpy="0 0 0" xyz="-0.030816858139 0.004617229294 0.000893125713"/>      
            <mass value="0.207204302"/>      
            <inertia ixx="0.0002104880248" ixy="-5.6750980345e-05" ixz="-1.0127699391e-05" iyy="0.000676270210023" iyz="8.22869024e-07" izz="0.000545032674924"/>    
        </inertial>  
    </link>  
    <!-- Shank joint -->  
    <joint name="RH_KFE" type="revolute">    
        <parent link="RH_THIGH"/>    
        <child link="RH_SHANK"/>    
        <origin xyz="-0.0 -0.109 -0.25"/>    
        <axis xyz="0 1 0"/>    
        <limit command_effort="40" current="10" effort="80" gear_velocity="10" lower="-9.42" upper="9.42" velocity="15.0"/>    
        <dynamics damping="0.0" friction="0.0"/>  
    </joint>  
    <!-- Shank to Adapter joint -->  
    <joint name="RH_SHANK_TO_ADAPTER" type="fixed">    
        <parent link="RH_SHANK"/>    
        <child link="RH_ADAPTER"/>    
        <origin rpy="-0.0 -0.0 0.0" xyz="-0.1 0.02 0.0"/>  
    </joint>  
    <!-- Adapter link -->  
    <link name="RH_ADAPTER">    
        <visual>      
            <origin rpy="0 0 -3.14159265359" xyz="0 0 0.032"/>      
            <geometry>        
                <mesh filename="package://anymal_b_simple_description/meshes/anymal_foot.dae" scale="0.001 0.001     0.001"/>      
            </geometry>      
            <material name="anymal_material"/>    
        </visual>    
        <collision>      
            <origin rpy="0 0 0" xyz="0 0 -0.160625"/>      
            <geometry>        
                <cylinder length="0.32125" radius="0.015"/>      
            </geometry>      
            <material name="anymal_material"/>    
        </collision>    
        <inertial>      
            <origin rpy="0 0 0" xyz="-8.66e-10 -1.472e-09 -0.244345749188"/>      
            <mass value="0.140170767"/>      
            <inertia ixx="0.00159938741862" ixy="-9.32e-13" ixz="1.039e-11" iyy="0.00159938741932" iyz="1.7563e-11" izz="5.4423177329e-05"/>    
        </inertial>  
    </link>  
    <!-- Adapter to Foot joint -->  
    <joint name="RH_ADAPTER_TO_FOOT" type="fixed">    
        <parent link="RH_ADAPTER"/>    
        <child link="RH_FOOT"/>    
        <origin rpy="-0.0 -0.0 0.0" xyz="-0.0 -0.0 -0.32125"/>  
    </joint>  
    <!-- Foot link -->  
    <link name="RH_FOOT">    
 	<inertial >
            <origin xyz="0 0 0.02325" rpy="0 0 0"/>
            <mass value="0.140170767" />
            <inertia ixx="1.28e-06" ixy="0.0" ixz="0.0" iyy="1.28e-06" iyz="0.0" izz="1.28e-06"/>
        </inertial>    
        <collision name="RH_FOOT_collision">      
            <origin xyz="0 0 0.02325" rpy="0 0 0"/>      
            <geometry>        
                <sphere radius="0.031"/>      
            </geometry>    
        </collision>  
	<visual>
            <origin rpy="0.0 0 0" xyz="0 0 0"/>
            <geometry>
                <sphere radius="0.031"/>
            </geometry>
        </visual>
    </link>  

    <!-- Gazebo customization -->  
    <gazebo reference="RH_FOOT">   
	<sensor name="RH_FOOT_CONTACTSENSOR" type="contact">
	    <alwaysOn>true</alwaysOn>
	    <updateRate>30</updateRate>
	    <contact>
		<collision>RH_FOOT_collision_collision_1</collision>
	    </contact>
	    <plugin name="bumper0_plugin" filename="libgazebo_ros_bumper.so">
		<bumperTopicName>rh_foot_contactsensor_state</bumperTopicName>
		<frameName>rh_foot_contactsesnor_link</frameName>
	    </plugin>
	</sensor> 
        <kp>400.0</kp>
        <kd>10.0</kd>    
<!--        <mu1>1000000.0</mu1>
        <mu2>1000000.0</mu2>-->
        <mu1>0.8</mu1>
        <mu2>0.8</mu2>
    </gazebo> 

    <gazebo>
        <plugin name="gazebo_ros_control" filename="libgazebo_ros_control.so">
      	    <robotNamespace>/anymal</robotNamespace>
            <robotSimType>gazebo_ros_control/DefaultRobotHWSim</robotSimType>
            <legacyModeNS>true</legacyModeNS>
        </plugin>
    </gazebo>

    <gazebo>
	<plugin name="p3d_base_controller" filename="libgazebo_ros_p3d.so">
		<alwaysOn>true</alwaysOn>
		<updateRate>50.0</updateRate>
		<bodyName>base</bodyName>
		<topicName>odom</topicName>
		<gaussianNoise>0.01</gaussianNoise>
		<frameName>world</frameName>
		<xyzOffsets>0 0 0</xyzOffsets>
		<rpyOffsets>0 0 0</rpyOffsets>
	</plugin>
    </gazebo>

    <gazebo>
	<plugin name="gazebo_ros_imu_controller" filename="libgazebo_ros_imu.so">
	    <robotNamespace>/anymal</robotNamespace>
	    <topicName>imu/data2</topicName>
	    <serviceName>imu/service</serviceName>
	    <bodyName>base</bodyName>
	    <gaussianNoise>0</gaussianNoise>
	    <rpyOffsets>0 0 0</rpyOffsets>
	    <updateRate>50.0</updateRate>
	    <alwaysOn>true</alwaysOn>
	</plugin>
    </gazebo>

<!-- D435i -->
    <plugin name="realsense_plugin" filename="libRealSensePlugin.so"/>
    <joint name="base_to_realsense" type="fixed">    
        <parent link="base"/>    
        <child link="realsense"/>    
        <!--<origin rpy="0.0 0.0 0.0" xyz="0.0 0.0 0.21"/>-->
	<origin rpy="0 0 0" xyz="0.40 0.00 0.150"/>  
    </joint>
    <!--<pose frame="">0 0 0.015 0 0 0</pose>-->
    <link name="realsense">    
        <visual>      
            <origin rpy="0 0 0" xyz="0 0 0"/>      
            <geometry>        
                <mesh filename="package://anymal_b_simple_description/meshes/realsense.dae" scale="1 1 1"/>      
            </geometry>      
            <material name="realsense_diffuse"/>    
        </visual>    
        <collision>      
            <origin rpy="0 0 0" xyz="0 0 0"/>      
            <geometry>        
              <box size="0.090 0.025 0.025"/>      
            </geometry>
        </collision>	
        <inertial>      
        <origin rpy="0 0 0" xyz="0 0 0"/>      
            <mass value="0.0615752"/>      
            <inertia ixx="9.108e-05" ixy="0" ixz="0" iyy="2.51e-06" iyz="0" izz="8.931e-05"/>    
        </inertial>  
    </link>

<!-- multi camera-->
    <gazebo reference="realsense">
      <sensor name="stereo_camera" type="multicamera">
        <pose frame="">0 0.01 0.004 0 0 0</pose>
        <update_rate>30.0</update_rate>
        <camera name="realsense_left">
          <horizontal_fov>1.047198</horizontal_fov>
          <image>
            <width>640</width>
            <height>480</height>
            <format>RGB_INT8</format>
          </image>
          <clip>
            <near>0.1</near>
            <far>100</far>
          </clip>
          <noise>
            <type>gaussian</type>
            <mean>0.0</mean>
            <stddev>0.007</stddev>
          </noise>
        </camera>
	<camera name="realsense_right">
        <pose>0 -0.06 0.004 0 0 0</pose>
          <horizontal_fov>1.047198</horizontal_fov>
          <image>
            <width>640</width>
            <height>480</height>
            <format>RGB_INT8</format>
          </image>
          <clip>
            <near>0.1</near>
            <far>100</far>
          </clip>
          <noise>
            <type>gaussian</type>
            <mean>0.0</mean>
            <stddev>0.007</stddev>
          </noise>
        </camera>
        <plugin name="stereo_camera_controller" filename="libgazebo_ros_multicamera.so">
          <alwaysOn>true</alwaysOn>
          <updateRate>0.0</updateRate>
          <cameraName>realsense_d435i/camera</cameraName>
          <imageTopicName>image_raw</imageTopicName>
          <cameraInfoTopicName>camera_info</cameraInfoTopicName>
          <frameName>left_camera_optical_frame</frameName>
          <!--<rightFrameName>right_camera_optical_frame</rightFrameName>-->
          <hackBaseline>0.07</hackBaseline>
          <distortionK1>0.0</distortionK1>
          <distortionK2>0.0</distortionK2>
          <distortionK3>0.0</distortionK3>
          <distortionT1>0.0</distortionT1>
          <distortionT2>0.0</distortionT2>
        </plugin>
      </sensor>
    </gazebo> 

<!-- single camera
    <gazebo reference="realsense">
      <sensor name="camera1" type="camera">
        <pose frame="">0 -0.046 0.004 0 0 0</pose>
        <update_rate>30.0</update_rate>
        <camera name="realsense">
          <horizontal_fov>1.047198</horizontal_fov>
          <image>
            <width>1920</width>
            <height>1080</height>
            <format>RGB_INT8</format>
          </image>
          <clip>
            <near>0.1</near>
            <far>100</far>
          </clip>
          <noise>
            <type>gaussian</type>
            <mean>0.0</mean>
            <stddev>0.007</stddev>
          </noise>
        </camera>
-->

<!-- depth
        <plugin name="camera_plugin" filename="libgazebo_ros_openni_kinect.so">
          <baseline>0.2</baseline>
          <alwaysOn>true</alwaysOn>
          <updateRate>0.0</updateRate>
          <cameraName>camera_ir</cameraName>
          <imageTopicName>/camera/color/image_raw</imageTopicName>
          <cameraInfoTopicName>/camera/color/camera_info</cameraInfoTopicName>
          <depthImageTopicName>/camera/depth/image_raw</depthImageTopicName>
          <depthImageCameraInfoTopicName>/camera/depth/camera_info</depthImageCameraInfoTopicName>
          <pointCloudTopicName>/camera/depth/points</pointCloudTopicName>
          <frameName>camera_link</frameName>
          <pointCloudCutoff>0.5</pointCloudCutoff>
          <pointCloudCutoffMax>3.0</pointCloudCutoffMax>
          <distortionK1>0</distortionK1>
          <distortionK2>0</distortionK2>
          <distortionK3>0</distortionK3>
          <distortionT1>0</distortionT1>
          <distortionT2>0</distortionT2>
          <CxPrime>0</CxPrime>
          <Cx>0</Cx>
          <Cy>0</Cy>
          <.focalLength>0</focalLength>
          <hackBaseline>0</hackBaseline>
        </plugin>
-->

<!-- single camera
        <plugin name="camera_controller" filename="libgazebo_ros_camera.so">
          <alwaysOn>true</alwaysOn>
          <updateRate>0.0</updateRate>
          <cameraName>camera1</cameraName>
          <imageTopicName>image_raw</imageTopicName>
          <cameraInfoTopicName>camera_info</cameraInfoTopicName>
          <frameName>realsense</frameName>
          <hackBaseline>0.07</hackBaseline>
          <distortionK1>0.0</distortionK1>
          <distortionK2>0.0</distortionK2>
          <distortionK3>0.0</distortionK3>
          <distortionT1>0.0</distortionT1>
          <distortionT2>0.0</distortionT2>
        </plugin>

      </sensor>
    </gazebo> -->

    <transmission name="LF_HAA_TRANS">
	<type>transmission_interface/SimpleTransmission</type>
	<joint name="LF_HAA">
	    <hardwareInterface>hardware_interface/EffortJointInterface</hardwareInterface>
	</joint>
	<actuator name="LF_HAA_MOTOR">
	    <hardwareInterface>hardware_interface/EffortJointInterface</hardwareInterface>
	    <mechanicalReduction>1</mechanicalReduction>
	</actuator>
    </transmission>

    <transmission name="LF_HFE_TRANS">
	<type>transmission_interface/SimpleTransmission</type>
	<joint name="LF_HFE">
	    <hardwareInterface>hardware_interface/EffortJointInterface</hardwareInterface>
	</joint>
	<actuator name="LF_HFE_MOTOR">
	    <hardwareInterface>hardware_interface/EffortJointInterface</hardwareInterface>
	    <mechanicalReduction>1</mechanicalReduction>
	</actuator>
    </transmission>

    <transmission name="LF_KFE_TRANS">
	<type>transmission_interface/SimpleTransmission</type>
	<joint name="LF_KFE">
	    <hardwareInterface>hardware_interface/EffortJointInterface</hardwareInterface>
	</joint>
	<actuator name="LF_KFE_MOTOR">
	    <hardwareInterface>hardware_interface/EffortJointInterface</hardwareInterface>
	    <mechanicalReduction>1</mechanicalReduction>
	</actuator>
    </transmission>

    <transmission name="LH_HAA_TRANS">
	<type>transmission_interface/SimpleTransmission</type>
	<joint name="LH_HAA">
	    <hardwareInterface>hardware_interface/EffortJointInterface</hardwareInterface>
	</joint>
	<actuator name="LH_HAA_MOTOR">
	    <hardwareInterface>hardware_interface/EffortJointInterface</hardwareInterface>
	    <mechanicalReduction>1</mechanicalReduction>
	</actuator>
    </transmission>

    <transmission name="LH_HFE_TRANS">
	<type>transmission_interface/SimpleTransmission</type>
	<joint name="LH_HFE">
	    <hardwareInterface>hardware_interface/EffortJointInterface</hardwareInterface>
	</joint>
	<actuator name="LH_HFE_MOTOR">
	    <hardwareInterface>hardware_interface/EffortJointInterface</hardwareInterface>
	    <mechanicalReduction>1</mechanicalReduction>
	</actuator>
    </transmission>

    <transmission name="LH_KFE_TRANS">
	<type>transmission_interface/SimpleTransmission</type>
	<joint name="LH_KFE">
	    <hardwareInterface>hardware_interface/EffortJointInterface</hardwareInterface>
	</joint>
	<actuator name="LH_KFE_MOTOR">
	    <hardwareInterface>hardware_interface/EffortJointInterface</hardwareInterface>
	    <mechanicalReduction>1</mechanicalReduction>
	</actuator>
    </transmission>

    <transmission name="RF_HAA_TRANS">
	<type>transmission_interface/SimpleTransmission</type>
	<joint name="RF_HAA">
	    <hardwareInterface>hardware_interface/EffortJointInterface</hardwareInterface>
	</joint>
	<actuator name="RF_HAA_MOTOR">
	    <hardwareInterface>hardware_interface/EffortJointInterface</hardwareInterface>
	    <mechanicalReduction>1</mechanicalReduction>
	</actuator>
    </transmission>

    <transmission name="RF_HFE_TRANS">
	<type>transmission_interface/SimpleTransmission</type>
	<joint name="RF_HFE">
	    <hardwareInterface>hardware_interface/EffortJointInterface</hardwareInterface>
	</joint>
	<actuator name="RF_HFE_MOTOR">
	    <hardwareInterface>hardware_interface/EffortJointInterface</hardwareInterface>
	    <mechanicalReduction>1</mechanicalReduction>
	</actuator>
    </transmission>

    <transmission name="RF_KFE_TRANS">
	<type>transmission_interface/SimpleTransmission</type>
	<joint name="RF_KFE">
	    <hardwareInterface>hardware_interface/EffortJointInterface</hardwareInterface>
	</joint>
	<actuator name="RF_KFE_MOTOR">
	    <hardwareInterface>hardware_interface/EffortJointInterface</hardwareInterface>
	    <mechanicalReduction>1</mechanicalReduction>
	</actuator>
    </transmission>

    <transmission name="RH_HAA_TRANS">
	<type>transmission_interface/SimpleTransmission</type>
	<joint name="RH_HAA">
	    <hardwareInterface>hardware_interface/EffortJointInterface</hardwareInterface>
	</joint>
	<actuator name="RH_HAA_MOTOR">
	    <hardwareInterface>hardware_interface/EffortJointInterface</hardwareInterface>
	    <mechanicalReduction>1</mechanicalReduction>
	</actuator>
    </transmission>

    <transmission name="RH_HFE_TRANS">
	<type>transmission_interface/SimpleTransmission</type>
	<joint name="RH_HFE">
	    <hardwareInterface>hardware_interface/EffortJointInterface</hardwareInterface>
	</joint>
	<actuator name="RH_HFE_MOTOR">
	    <hardwareInterface>hardware_interface/EffortJointInterface</hardwareInterface>
	    <mechanicalReduction>1</mechanicalReduction>
	</actuator>
    </transmission>

    <transmission name="RH_KFE_TRANS">
	<type>transmission_interface/SimpleTransmission</type>
	<joint name="RH_KFE">
	    <hardwareInterface>hardware_interface/EffortJointInterface</hardwareInterface>
	</joint>
	<actuator name="RH_KFE_MOTOR">
	    <hardwareInterface>hardware_interface/EffortJointInterface</hardwareInterface>
	    <mechanicalReduction>1</mechanicalReduction>
	</actuator>
    </transmission>
</robot>

